22-03-23 16:40:27 	 ERROR 	 utils.py - try5times_wrapper: 	 Error found when running <function CommsHuobi.get_next_funding_rate at 0x000001961B7874C0>.
Traceback (most recent call last):
  File "C:\Users\micha\Documents\XXX Capital Management\Code\new_crypto_program\scripts\utils.py", line 14, in try5times_wrapper
    return function(self, *args, **kwargs)
  File "c:\Users\micha\Documents\XXX Capital Management\Code\new_crypto_program\scripts\comms_huobi.py", line 95, in get_next_funding_rate
    funding_rates[pair] = float(data_dict['funding_rate'])
TypeError: float() argument must be a string or a number, not 'NoneType'
22-03-23 16:40:28 	 ERROR 	 utils.py - try5times_wrapper: 	 Error found when running <function CommsHuobi.get_next_funding_rate at 0x000001961B7874C0>.
Traceback (most recent call last):
  File "C:\Users\micha\Documents\XXX Capital Management\Code\new_crypto_program\scripts\utils.py", line 14, in try5times_wrapper
    return function(self, *args, **kwargs)
  File "c:\Users\micha\Documents\XXX Capital Management\Code\new_crypto_program\scripts\comms_huobi.py", line 95, in get_next_funding_rate
    funding_rates[pair] = float(data_dict['funding_rate'])
TypeError: float() argument must be a string or a number, not 'NoneType'
22-03-23 16:40:29 	 ERROR 	 utils.py - try5times_wrapper: 	 Error found when running <function CommsHuobi.get_next_funding_rate at 0x000001961B7874C0>.
Traceback (most recent call last):
  File "C:\Users\micha\Documents\XXX Capital Management\Code\new_crypto_program\scripts\utils.py", line 14, in try5times_wrapper
    return function(self, *args, **kwargs)
  File "c:\Users\micha\Documents\XXX Capital Management\Code\new_crypto_program\scripts\comms_huobi.py", line 95, in get_next_funding_rate
    funding_rates[pair] = float(data_dict['funding_rate'])
TypeError: float() argument must be a string or a number, not 'NoneType'
22-03-23 16:40:31 	 ERROR 	 utils.py - try5times_wrapper: 	 Error found when running <function CommsHuobi.get_next_funding_rate at 0x000001961B7874C0>.
Traceback (most recent call last):
  File "C:\Users\micha\Documents\XXX Capital Management\Code\new_crypto_program\scripts\utils.py", line 14, in try5times_wrapper
    return function(self, *args, **kwargs)
  File "c:\Users\micha\Documents\XXX Capital Management\Code\new_crypto_program\scripts\comms_huobi.py", line 95, in get_next_funding_rate
    funding_rates[pair] = float(data_dict['funding_rate'])
TypeError: float() argument must be a string or a number, not 'NoneType'
22-03-23 16:40:34 	 ERROR 	 utils.py - try5times_wrapper: 	 Error found when running <function CommsHuobi.get_next_funding_rate at 0x000001961B7874C0>.
Traceback (most recent call last):
  File "C:\Users\micha\Documents\XXX Capital Management\Code\new_crypto_program\scripts\utils.py", line 14, in try5times_wrapper
    return function(self, *args, **kwargs)
  File "c:\Users\micha\Documents\XXX Capital Management\Code\new_crypto_program\scripts\comms_huobi.py", line 95, in get_next_funding_rate
    funding_rates[pair] = float(data_dict['funding_rate'])
TypeError: float() argument must be a string or a number, not 'NoneType'
22-03-23 16:40:34 	 CRITICAL 	 utils.py - try5times_wrapper: 	 <function CommsHuobi.get_next_funding_rate at 0x000001961B7874C0> failed to work after 5 attempts.
22-03-24 00:29:20 	 ERROR 	 utils.py - try5times_wrapper: 	 Error found when running <function CommsHuobi.get_historical_funding_rates at 0x000002BBB50E3280>.
Traceback (most recent call last):
  File "C:\Users\micha\Documents\XXX Capital Management\Code\new_crypto_program\scripts\utils.py", line 14, in try5times_wrapper
    return function(self, *args, **kwargs)
TypeError: get_historical_funding_rates() takes 2 positional arguments but 3 were given
22-03-24 00:29:20 	 ERROR 	 utils.py - try5times_wrapper: 	 Error found when running <function CommsHuobi.get_historical_funding_rates at 0x000002BBB50E3280>.
Traceback (most recent call last):
  File "C:\Users\micha\Documents\XXX Capital Management\Code\new_crypto_program\scripts\utils.py", line 14, in try5times_wrapper
    return function(self, *args, **kwargs)
TypeError: get_historical_funding_rates() takes 2 positional arguments but 3 were given
22-03-24 00:29:21 	 ERROR 	 utils.py - try5times_wrapper: 	 Error found when running <function CommsHuobi.get_historical_funding_rates at 0x000002BBB50E3280>.
Traceback (most recent call last):
  File "C:\Users\micha\Documents\XXX Capital Management\Code\new_crypto_program\scripts\utils.py", line 14, in try5times_wrapper
    return function(self, *args, **kwargs)
TypeError: get_historical_funding_rates() takes 2 positional arguments but 3 were given
22-03-24 00:29:23 	 ERROR 	 utils.py - try5times_wrapper: 	 Error found when running <function CommsHuobi.get_historical_funding_rates at 0x000002BBB50E3280>.
Traceback (most recent call last):
  File "C:\Users\micha\Documents\XXX Capital Management\Code\new_crypto_program\scripts\utils.py", line 14, in try5times_wrapper
    return function(self, *args, **kwargs)
TypeError: get_historical_funding_rates() takes 2 positional arguments but 3 were given
22-03-24 00:29:25 	 ERROR 	 utils.py - try5times_wrapper: 	 Error found when running <function CommsHuobi.get_historical_funding_rates at 0x000002BBB50E3280>.
Traceback (most recent call last):
  File "C:\Users\micha\Documents\XXX Capital Management\Code\new_crypto_program\scripts\utils.py", line 14, in try5times_wrapper
    return function(self, *args, **kwargs)
TypeError: get_historical_funding_rates() takes 2 positional arguments but 3 were given
22-03-24 00:29:25 	 CRITICAL 	 utils.py - try5times_wrapper: 	 <function CommsHuobi.get_historical_funding_rates at 0x000002BBB50E3280> failed to work after 5 attempts.
22-03-24 00:40:07 	 ERROR 	 utils.py - try5times_wrapper: 	 Error found when running <function CommsHuobi.get_historical_funding_rates at 0x000001A712243310>.
Traceback (most recent call last):
  File "C:\Users\micha\Documents\XXX Capital Management\Code\new_crypto_program\scripts\utils.py", line 14, in try5times_wrapper
    return function(self, *args, **kwargs)
  File "c:\Users\micha\Documents\XXX Capital Management\Code\new_crypto_program\scripts\comms_huobi.py", line 138, in get_historical_funding_rates
    url = f'{self.huobi_url}/swap-api/v1/swap_historical_funding_rate'
AttributeError: 'CommsHuobi' object has no attribute 'huobi_url'
22-03-24 00:41:06 	 ERROR 	 utils.py - try5times_wrapper: 	 Error found when running <function CommsHuobi.get_historical_funding_rates at 0x000001A712243310>.
Traceback (most recent call last):
  File "C:\Users\micha\Documents\XXX Capital Management\Code\new_crypto_program\scripts\utils.py", line 14, in try5times_wrapper
    return function(self, *args, **kwargs)
  File "c:\Users\micha\Documents\XXX Capital Management\Code\new_crypto_program\scripts\comms_huobi.py", line 138, in get_historical_funding_rates
    url = f'{self.huobi_url}/swap-api/v1/swap_historical_funding_rate'
AttributeError: 'CommsHuobi' object has no attribute 'huobi_url'
22-03-24 00:42:19 	 ERROR 	 utils.py - try5times_wrapper: 	 Error found when running <function CommsHuobi.get_historical_funding_rates at 0x000001A712243310>.
Traceback (most recent call last):
  File "C:\Users\micha\Documents\XXX Capital Management\Code\new_crypto_program\scripts\utils.py", line 14, in try5times_wrapper
    return function(self, *args, **kwargs)
  File "c:\Users\micha\Documents\XXX Capital Management\Code\new_crypto_program\scripts\comms_huobi.py", line 138, in get_historical_funding_rates
    url = f'{self.huobi_url}/swap-api/v1/swap_historical_funding_rate'
AttributeError: 'CommsHuobi' object has no attribute 'huobi_url'
22-03-31 20:04:23 	 ERROR 	 utils.py - try5times_wrapper: 	 Error found when running <function CommsHuobi.get_historical_funding_rates at 0x00000196A8D00550>.
Traceback (most recent call last):
  File "C:\Users\micha\Documents\XXX Capital Management\Code\new_crypto_program\scripts\utils.py", line 14, in try5times_wrapper
    return function(self, *args, **kwargs)
TypeError: get_historical_funding_rates() got an unexpected keyword argument 'pair_tuples'
22-03-31 20:04:24 	 ERROR 	 utils.py - try5times_wrapper: 	 Error found when running <function CommsHuobi.get_historical_funding_rates at 0x00000196A8D00550>.
Traceback (most recent call last):
  File "C:\Users\micha\Documents\XXX Capital Management\Code\new_crypto_program\scripts\utils.py", line 14, in try5times_wrapper
    return function(self, *args, **kwargs)
TypeError: get_historical_funding_rates() got an unexpected keyword argument 'pair_tuples'
22-03-31 20:04:24 	 ERROR 	 utils.py - try5times_wrapper: 	 Error found when running <function CommsHuobi.get_historical_funding_rates at 0x00000196A8D00550>.
Traceback (most recent call last):
  File "C:\Users\micha\Documents\XXX Capital Management\Code\new_crypto_program\scripts\utils.py", line 14, in try5times_wrapper
    return function(self, *args, **kwargs)
TypeError: get_historical_funding_rates() got an unexpected keyword argument 'pair_tuples'
22-03-31 20:04:26 	 ERROR 	 utils.py - try5times_wrapper: 	 Error found when running <function CommsHuobi.get_historical_funding_rates at 0x00000196A8D00550>.
Traceback (most recent call last):
  File "C:\Users\micha\Documents\XXX Capital Management\Code\new_crypto_program\scripts\utils.py", line 14, in try5times_wrapper
    return function(self, *args, **kwargs)
TypeError: get_historical_funding_rates() got an unexpected keyword argument 'pair_tuples'
22-03-31 20:04:28 	 ERROR 	 utils.py - try5times_wrapper: 	 Error found when running <function CommsHuobi.get_historical_funding_rates at 0x00000196A8D00550>.
Traceback (most recent call last):
  File "C:\Users\micha\Documents\XXX Capital Management\Code\new_crypto_program\scripts\utils.py", line 14, in try5times_wrapper
    return function(self, *args, **kwargs)
TypeError: get_historical_funding_rates() got an unexpected keyword argument 'pair_tuples'
22-03-31 20:04:28 	 CRITICAL 	 utils.py - try5times_wrapper: 	 <function CommsHuobi.get_historical_funding_rates at 0x00000196A8D00550> failed to work after 5 attempts.
22-03-31 20:04:58 	 ERROR 	 utils.py - try5times_wrapper: 	 Error found when running <function CommsHuobi.get_historical_funding_rates at 0x000001D5A7132550>.
Traceback (most recent call last):
  File "C:\Users\micha\Documents\XXX Capital Management\Code\new_crypto_program\scripts\utils.py", line 14, in try5times_wrapper
    return function(self, *args, **kwargs)
  File "c:\Users\micha\Documents\XXX Capital Management\Code\new_crypto_program\scripts\comms_huobi.py", line 205, in get_historical_funding_rates
    'datetime': datetime.fromtimestamp(int(time_dict['funding_time'])/1000),
TypeError: string indices must be integers
22-03-31 20:05:00 	 ERROR 	 utils.py - try5times_wrapper: 	 Error found when running <function CommsHuobi.get_historical_funding_rates at 0x000001D5A7132550>.
Traceback (most recent call last):
  File "C:\Users\micha\Documents\XXX Capital Management\Code\new_crypto_program\scripts\utils.py", line 14, in try5times_wrapper
    return function(self, *args, **kwargs)
  File "c:\Users\micha\Documents\XXX Capital Management\Code\new_crypto_program\scripts\comms_huobi.py", line 205, in get_historical_funding_rates
    'datetime': datetime.fromtimestamp(int(time_dict['funding_time'])/1000),
TypeError: string indices must be integers
22-03-31 20:05:02 	 ERROR 	 utils.py - try5times_wrapper: 	 Error found when running <function CommsHuobi.get_historical_funding_rates at 0x000001D5A7132550>.
Traceback (most recent call last):
  File "C:\Users\micha\Documents\XXX Capital Management\Code\new_crypto_program\scripts\utils.py", line 14, in try5times_wrapper
    return function(self, *args, **kwargs)
  File "c:\Users\micha\Documents\XXX Capital Management\Code\new_crypto_program\scripts\comms_huobi.py", line 205, in get_historical_funding_rates
    'datetime': datetime.fromtimestamp(int(time_dict['funding_time'])/1000),
TypeError: string indices must be integers
22-03-31 20:05:05 	 ERROR 	 utils.py - try5times_wrapper: 	 Error found when running <function CommsHuobi.get_historical_funding_rates at 0x000001D5A7132550>.
Traceback (most recent call last):
  File "C:\Users\micha\Documents\XXX Capital Management\Code\new_crypto_program\scripts\utils.py", line 14, in try5times_wrapper
    return function(self, *args, **kwargs)
  File "c:\Users\micha\Documents\XXX Capital Management\Code\new_crypto_program\scripts\comms_huobi.py", line 205, in get_historical_funding_rates
    'datetime': datetime.fromtimestamp(int(time_dict['funding_time'])/1000),
TypeError: string indices must be integers
22-03-31 20:05:09 	 ERROR 	 utils.py - try5times_wrapper: 	 Error found when running <function CommsHuobi.get_historical_funding_rates at 0x000001D5A7132550>.
Traceback (most recent call last):
  File "C:\Users\micha\Documents\XXX Capital Management\Code\new_crypto_program\scripts\utils.py", line 14, in try5times_wrapper
    return function(self, *args, **kwargs)
  File "c:\Users\micha\Documents\XXX Capital Management\Code\new_crypto_program\scripts\comms_huobi.py", line 205, in get_historical_funding_rates
    'datetime': datetime.fromtimestamp(int(time_dict['funding_time'])/1000),
TypeError: string indices must be integers
22-03-31 20:05:09 	 CRITICAL 	 utils.py - try5times_wrapper: 	 <function CommsHuobi.get_historical_funding_rates at 0x000001D5A7132550> failed to work after 5 attempts.
22-03-31 20:11:39 	 ERROR 	 utils.py - try5times_wrapper: 	 Error found when running <function CommsHuobi.get_next_funding_rate at 0x0000023E0D972430>.
Traceback (most recent call last):
  File "C:\Users\micha\Documents\XXX Capital Management\Code\new_crypto_program\scripts\utils.py", line 14, in try5times_wrapper
    return function(self, *args, **kwargs)
  File "c:\Users\micha\Documents\XXX Capital Management\Code\new_crypto_program\scripts\comms_huobi.py", line 116, in get_next_funding_rate
    'datetime': datetime.fromtimestamp(int(time_dict['funding_time'])/1000),
NameError: name 'time_dict' is not defined
22-03-31 20:11:41 	 ERROR 	 utils.py - try5times_wrapper: 	 Error found when running <function CommsHuobi.get_next_funding_rate at 0x0000023E0D972430>.
Traceback (most recent call last):
  File "C:\Users\micha\Documents\XXX Capital Management\Code\new_crypto_program\scripts\utils.py", line 14, in try5times_wrapper
    return function(self, *args, **kwargs)
  File "c:\Users\micha\Documents\XXX Capital Management\Code\new_crypto_program\scripts\comms_huobi.py", line 116, in get_next_funding_rate
    'datetime': datetime.fromtimestamp(int(time_dict['funding_time'])/1000),
NameError: name 'time_dict' is not defined
22-03-31 20:11:43 	 ERROR 	 utils.py - try5times_wrapper: 	 Error found when running <function CommsHuobi.get_next_funding_rate at 0x0000023E0D972430>.
Traceback (most recent call last):
  File "C:\Users\micha\Documents\XXX Capital Management\Code\new_crypto_program\scripts\utils.py", line 14, in try5times_wrapper
    return function(self, *args, **kwargs)
  File "c:\Users\micha\Documents\XXX Capital Management\Code\new_crypto_program\scripts\comms_huobi.py", line 116, in get_next_funding_rate
    'datetime': datetime.fromtimestamp(int(time_dict['funding_time'])/1000),
NameError: name 'time_dict' is not defined
22-03-31 20:11:45 	 ERROR 	 utils.py - try5times_wrapper: 	 Error found when running <function CommsHuobi.get_next_funding_rate at 0x0000023E0D972430>.
Traceback (most recent call last):
  File "C:\Users\micha\Documents\XXX Capital Management\Code\new_crypto_program\scripts\utils.py", line 14, in try5times_wrapper
    return function(self, *args, **kwargs)
  File "c:\Users\micha\Documents\XXX Capital Management\Code\new_crypto_program\scripts\comms_huobi.py", line 116, in get_next_funding_rate
    'datetime': datetime.fromtimestamp(int(time_dict['funding_time'])/1000),
NameError: name 'time_dict' is not defined
22-03-31 20:11:48 	 ERROR 	 utils.py - try5times_wrapper: 	 Error found when running <function CommsHuobi.get_next_funding_rate at 0x0000023E0D972430>.
Traceback (most recent call last):
  File "C:\Users\micha\Documents\XXX Capital Management\Code\new_crypto_program\scripts\utils.py", line 14, in try5times_wrapper
    return function(self, *args, **kwargs)
  File "c:\Users\micha\Documents\XXX Capital Management\Code\new_crypto_program\scripts\comms_huobi.py", line 116, in get_next_funding_rate
    'datetime': datetime.fromtimestamp(int(time_dict['funding_time'])/1000),
NameError: name 'time_dict' is not defined
22-03-31 20:11:48 	 CRITICAL 	 utils.py - try5times_wrapper: 	 <function CommsHuobi.get_next_funding_rate at 0x0000023E0D972430> failed to work after 5 attempts.
22-03-31 20:16:56 	 ERROR 	 utils.py - try5times_wrapper: 	 Error found when running <function CommsHuobi.get_next_funding_rate at 0x00000264F66C2430>.
Traceback (most recent call last):
  File "C:\Users\micha\Documents\XXX Capital Management\Code\new_crypto_program\scripts\utils.py", line 14, in try5times_wrapper
    return function(self, *args, **kwargs)
  File "c:\Users\micha\Documents\XXX Capital Management\Code\new_crypto_program\scripts\comms_huobi.py", line 116, in get_next_funding_rate
    'datetime': datetime.fromtimestamp(int(time_dict['funding_time'])/1000),
NameError: name 'time_dict' is not defined
22-03-31 20:16:57 	 ERROR 	 utils.py - try5times_wrapper: 	 Error found when running <function CommsHuobi.get_next_funding_rate at 0x00000264F66C2430>.
Traceback (most recent call last):
  File "C:\Users\micha\Documents\XXX Capital Management\Code\new_crypto_program\scripts\utils.py", line 14, in try5times_wrapper
    return function(self, *args, **kwargs)
  File "c:\Users\micha\Documents\XXX Capital Management\Code\new_crypto_program\scripts\comms_huobi.py", line 116, in get_next_funding_rate
    'datetime': datetime.fromtimestamp(int(time_dict['funding_time'])/1000),
NameError: name 'time_dict' is not defined
22-03-31 20:16:59 	 ERROR 	 utils.py - try5times_wrapper: 	 Error found when running <function CommsHuobi.get_next_funding_rate at 0x00000264F66C2430>.
Traceback (most recent call last):
  File "C:\Users\micha\Documents\XXX Capital Management\Code\new_crypto_program\scripts\utils.py", line 14, in try5times_wrapper
    return function(self, *args, **kwargs)
  File "c:\Users\micha\Documents\XXX Capital Management\Code\new_crypto_program\scripts\comms_huobi.py", line 116, in get_next_funding_rate
    'datetime': datetime.fromtimestamp(int(time_dict['funding_time'])/1000),
NameError: name 'time_dict' is not defined
22-03-31 20:17:02 	 ERROR 	 utils.py - try5times_wrapper: 	 Error found when running <function CommsHuobi.get_next_funding_rate at 0x00000264F66C2430>.
Traceback (most recent call last):
  File "C:\Users\micha\Documents\XXX Capital Management\Code\new_crypto_program\scripts\utils.py", line 14, in try5times_wrapper
    return function(self, *args, **kwargs)
  File "c:\Users\micha\Documents\XXX Capital Management\Code\new_crypto_program\scripts\comms_huobi.py", line 116, in get_next_funding_rate
    'datetime': datetime.fromtimestamp(int(time_dict['funding_time'])/1000),
NameError: name 'time_dict' is not defined
22-03-31 20:17:06 	 ERROR 	 utils.py - try5times_wrapper: 	 Error found when running <function CommsHuobi.get_next_funding_rate at 0x00000264F66C2430>.
Traceback (most recent call last):
  File "C:\Users\micha\Documents\XXX Capital Management\Code\new_crypto_program\scripts\utils.py", line 14, in try5times_wrapper
    return function(self, *args, **kwargs)
  File "c:\Users\micha\Documents\XXX Capital Management\Code\new_crypto_program\scripts\comms_huobi.py", line 116, in get_next_funding_rate
    'datetime': datetime.fromtimestamp(int(time_dict['funding_time'])/1000),
NameError: name 'time_dict' is not defined
22-03-31 20:17:06 	 CRITICAL 	 utils.py - try5times_wrapper: 	 <function CommsHuobi.get_next_funding_rate at 0x00000264F66C2430> failed to work after 5 attempts.
22-03-31 22:04:39 	 ERROR 	 utils.py - try5times_wrapper: 	 Error found when running <function CommsHuobi.get_next_funding_rate at 0x000001A8424494C0>.
Traceback (most recent call last):
  File "C:\Users\micha\Documents\XXX Capital Management\Code\new_crypto_program\scripts\utils.py", line 14, in try5times_wrapper
    return function(self, *args, **kwargs)
TypeError: get_next_funding_rate() missing 1 required positional argument: 'pairs'
22-03-31 22:04:40 	 ERROR 	 utils.py - try5times_wrapper: 	 Error found when running <function CommsHuobi.get_next_funding_rate at 0x000001A8424494C0>.
Traceback (most recent call last):
  File "C:\Users\micha\Documents\XXX Capital Management\Code\new_crypto_program\scripts\utils.py", line 14, in try5times_wrapper
    return function(self, *args, **kwargs)
TypeError: get_next_funding_rate() missing 1 required positional argument: 'pairs'
22-03-31 22:04:40 	 ERROR 	 utils.py - try5times_wrapper: 	 Error found when running <function CommsHuobi.get_next_funding_rate at 0x000001A8424494C0>.
Traceback (most recent call last):
  File "C:\Users\micha\Documents\XXX Capital Management\Code\new_crypto_program\scripts\utils.py", line 14, in try5times_wrapper
    return function(self, *args, **kwargs)
TypeError: get_next_funding_rate() missing 1 required positional argument: 'pairs'
22-03-31 22:04:42 	 ERROR 	 utils.py - try5times_wrapper: 	 Error found when running <function CommsHuobi.get_next_funding_rate at 0x000001A8424494C0>.
Traceback (most recent call last):
  File "C:\Users\micha\Documents\XXX Capital Management\Code\new_crypto_program\scripts\utils.py", line 14, in try5times_wrapper
    return function(self, *args, **kwargs)
TypeError: get_next_funding_rate() missing 1 required positional argument: 'pairs'
22-03-31 22:04:44 	 ERROR 	 utils.py - try5times_wrapper: 	 Error found when running <function CommsHuobi.get_next_funding_rate at 0x000001A8424494C0>.
Traceback (most recent call last):
  File "C:\Users\micha\Documents\XXX Capital Management\Code\new_crypto_program\scripts\utils.py", line 14, in try5times_wrapper
    return function(self, *args, **kwargs)
TypeError: get_next_funding_rate() missing 1 required positional argument: 'pairs'
22-03-31 22:04:44 	 CRITICAL 	 utils.py - try5times_wrapper: 	 <function CommsHuobi.get_next_funding_rate at 0x000001A8424494C0> failed to work after 5 attempts.
